Workbook

Sheet Özet
A1: HAZİNE İHALE VERİLERİ — ÖZET RAPORU
A2: Son Güncelleme: 29.10.2026 • Toplam 1644 İhale Kaydı • Kaynak: T.C. Hazine ve Maliye Bakanlığı
A4: Hazine 2024 yılının tamamında ortalama %37.56 faizle, 1564 gün vadeyle, toplamda 1,725.05 Milyar TL borçlanırken, 2025 yılının tamamında bu rakamlar sırasıyla %36.92, 1321 gün ve 2,503.71 Milyar TL olarak gerçekleşirken; 2026 yılında şuana kadar %35.00, 1272 gün ve 2,646.53 Milyar TL'dir. (Geçen yıl aynı dönemde %37.33, 1375 gün ve 2,284.21 Milyar TL)
A6: DÖNEMSEL KARŞILAŞTIRMA
A7: Dönem | B7: İhale Sayısı | C7: Ort. Faiz (%) | D7: Ort. Vade (Gün) | E7: İhale Başı Ort. (Bin TL) | F7: Toplam Net (Bin TL) | G7: Teklif/Kabul | H7: Yıllık Değişim
A8: 2024 (Tam Yıl) | B8: 96 | C8: 37.56 | D8: 1564 | E8: 20536297 | F8: 1725048919 | G8: 2.24 | H8: Baz Dönem
A9: 2025 (Tam Yıl) | B9: 72 | C9: 36.92 | D9: 1321 | E9: 40382361 | F9: 2503706352 | G9: 1.99 | H9: Faiz ↓ 0.64 puan
A10: 2026 (Ocak-Ekim) | B10: 62 | C10: 35 | D10: 1272 | E10: 49934575 | F10: 2646532458 | G10: 1.82 | H10: Faiz ↓ 2.33 puan
A11: 2025 (Ocak-Ekim) | B11: 63 | C11: 37.33 | D11: 1375 | E11: 41531002 | F11: 2284205131 | G11: 1.96 | H11: Baz Dönem
A13: DİKKAT ÇEKEN İSTATİSTİKLER
A14: 📉 Faiz Trendi (Aynı Dönem) | C14: 2025 Ocak-Ekim: %37.33 → 2026 Ocak-Ekim: %35.00 (-2.33 puan, faizler düştü)
A15: 📅 Vade Stratejisi | C15: Ort. vade 2025 Ocak-Ekim: 1375 gün → 2026: 1272 gün (kısaldı, -103 gün)
A16: 🏆 Tarihin En Büyük İhalesi | C16: TLREF Endeksli Senetler — 08.07.2026 — 157.78 Milyar TL
A17: 📊 2026 Ağırlıklı Senet Türü | C17: TL Cinsi Sabit Faizli Kuponlu Senetler (%40.7 pay)
A18: 💪 Talep Gücü (Teklif/Kabul) | C18: 2025 Ocak-Ekim: 1.96x → 2026: 1.82x (talep azaldı, -0.14x)
A19: 🔮 2026 Yıllık Projeksiyon | C19: İlk 10 ayda 2,646.53 Milyar TL → Yıl sonu tahmini: ~3,175.84 Milyar TL (2025 toplamı: 2,503.71 Milyar TL)
A20: ⚡ 2024 → 2025 Değişim | C20: Faiz: %37.56 → %36.92 (-0.64 puan), Toplam borçlanma: 1,725.05 Milyar TL → 2,503.71 Milyar TL (+45.1%)
A21: 📈 Dönemsel Borçlanma Hacmi | C21: 2025 Ocak-Ekim: 2,284.21 Milyar TL → 2026 Ocak-Ekim: 2,646.53 Milyar TL (+15.9% değişim)

Sheet Tüm İhaleler
A1: Genel Bilgiler | I1: Teklif Edilen Tutar | K1: İhale Kabul Edilen Tutar | M1: Rek. Olmayan Teklif - Kamu | O1: Rek. Olmayan Teklif - Piyasa Yapıcı | Q1: İhale Sonrası Satış | S1: Toplam Satış | U1: Kabul Edilen Faiz (%) | W1: Fiyat
A2: Senet Türü | B2: Yıl | C2: ISIN Kodu | D2: Valör Tarihi | E2: İtfa Tarihi | F2: Vade (Gün) | G2: Kupon Dönemi | H2: Kupon Oranı (%) | I2: Nominal (Bin TL) | J2: Net (Bin TL) | K2: Nominal (Bin TL) | L2: Net (Bin TL) | M2: Nominal (Bin TL) | N2: Net (Bin TL) | O2: Nominal (Bin TL) | P2: Net (Bin TL) | Q2: Nominal (Bin TL) | R2: Net (Bin TL) | S2: Nominal (Bin TL) | T2: Net (Bin TL) | U2: Ort. Dönem (Basit) | V2: Ort. Yıllık Bileşik | W2: İhraç Birim Fiyatı (Ort.)
A3: TLREF Endeksli Senetler | B3: 2026 | C3: TRT090130T12 | D3: 14.01.2026 | E3: 09.01.2030 | F3: 1456 | G3: 6 ay | I3: 79609005 | J3: 78023610 | K3: 29589001 | L3: 29392788 | M3: 22247501 | N3: 22100000 | O3: 23153508 | P3: 23000000 | Q3: 2098463.6 | R3: 2084550.8 | S3: 77088473 | T3: 76577339 | U3: 18.77 | V3: 41.05 | W3: 99.337
A4: TLREF Endeksli Senetler | B4: 2026 | C4: TRT090130T12 | D4: 11.02.2026 | E4: 09.01.2030 | F4: 1428 | G4: 6 ay | I4: 56562000 | J4: 58027619 | K4: 31595000 | L4: 32495975 | M4: 14972971 | N4: 15400000 | O4: 13611792 | P4: 14000000 | Q4: 8396267 | R4: 8635728.5 | S4: 68576030 | T4: 70531703 | U4: 18.55 | V4: 40.54 | W4: 102.852
A5: TLREF Endeksli Senetler | B5: 2026 | C5: TRT090130T12 | D5: 18.03.2026 | E5: 09.01.2030 | F5: 1393 | G5: 6 ay | I5: 81525000 | J5: 83978061 | K5: 16613000 | L5: 17209377 | M5: 9682401.8 | N5: 10030000 | O5: 19789555 | P5: 20500000 | Q5: 2606759.8 | R5: 2700342.5 | S5: 48691717 | T5: 50439720 | U5: 19.25 | V5: 42.19 | W5: 103.59
A6: TLREF Endeksli Senetler | B6: 2026 | C6: TRT090130T12 | D6: 08.04.2026 | E6: 09.01.2030 | F6: 1372 | G6: 6 ay | I6: 101723858 | J6: 1.0671121e+08 | K6: 62860858 | L6: 66117448 | M6: 190148.41 | N6: 200000 | O6: 31849859 | P6: 33500000 | Q6: 23923511 | R6: 25162988 | S6: 1.1882438e+08 | T6: 1.2498044e+08 | U6: 19.39 | V6: 42.53 | W6: 105.181
A7: TLREF Endeksli Senetler | B7: 2026 | C7: TRT090130T12 | D7: 13.05.2026 | E7: 09.01.2030 | F7: 1337 | G7: 6 ay | I7: 122200001 | J7: 1.3337384e+08 | K7: 40607001 | L7: 44450411 | M7: 1863609.4 | N7: 2040000 | O7: 36541360 | P7: 40000000 | Q7: 18248574 | R7: 19975802 | S7: 97260545 | T7: 1.0646621e+08 | U7: 19.22 | V7: 42.12 | W7: 109.465
A8: TLREF Endeksli Senetler | B8: 2026 | C8: TRT090130T12 | D8: 10.06.2026 | E8: 09.01.2030 | F8: 1309 | G8: 6 ay | I8: 104246000 | J8: 1.1700454e+08 | K8: 60642000 | L8: 68135035 | M8: 3586813.3 | N8: 4030000 | O8: 50731603 | P8: 57000000 | Q8: 25428457 | R8: 28570397 | S8: 1.4038887e+08 | T8: 1.5773543e+08 | U8: 19.25 | V8: 42.19 | W8: 112.356
A9: TLREF Endeksli Senetler | B9: 2026 | C9: TRT030730T12* | D9: 08.07.2026 | E9: 03.07.2030 | F9: 1456 | G9: 6 ay | I9: 1.4623886e+08 | J9: 1.4287476e+08 | K9: 75869822 | L9: 74576049 | M9: 3764179.3 | N9: 3700000 | O9: 80370314 | P9: 79000000 | Q9: 508672.87 | R9: 500000 | S9: 1.6051299e+08 | T9: 1.5777605e+08 | U9: 20.45 | V9: 45.08 | W9: 98.295
A10: TLREF Endeksli Senetler | B10: 2026 | C10: TRT030730T12 | D10: 19.08.2026 | E10: 03.07.2030 | F10: 1414 | G10: 6 ay | I10: 128932100 | J10: 1.3194076e+08 | K10: 32323100 | L10: 33159966 | M10: 97476.337 | N10: 99999.999 | O10: 53611986 | P10: 55000000 | Q10: 14802107 | R10: 15185333 | S10: 1.0083467e+08 | T10: 1.034453e+08 | U10: 20.46 | V10: 45.09 | W10: 102.589
A11: TLREF Endeksli Senetler | B11: 2026 | C11: TRT110930T36 | D11: 16.09.2026 | E11: 11.09.2030 | F11: 1456 | G11: 6 ay | I11: 113114000 | J11: 1.1046897e+08 | K11: 49631000 | L11: 48851315 | M11: 5486188 | N11: 5400000 | O11: 30478822 | P11: 30000000 | Q11: 0 | R11: 0 | S11: 85596010 | T11: 84251315 | U11: 18.64 | V11: 40.76 | W11: 98.429
A12: TLREF Endeksli Senetler | B12: 2026 | C12: TRT110930T36 | D12: 07.10.2026 | E12: 11.09.2030 | F12: 1435 | G12: 6 ay | I12: 58939000 | J12: 58617039 | K12: 26298000 | L12: 26217249 | M12: 0 | N12: 0 | O12: 25076986 | P12: 25000000 | Q12: 5300499.5 | R12: 5284227 | S12: 56675486 | T12: 56501476 | U12: 18.82 | V12: 41.18 | W12: 99.693
A13: TLREF Endeksli Senetler | B13: 2026 | C13: (*) İlgili ihalede yükümlülüğün yerine getirilmemesi sebebiyle, ihalede kabul edilen tutar ve toplam satış tutarlarında yukarıda belirtilen istatistiklerden nominal satış tutarı 175.000.000,00 TL; net satış tutarı ise 203.234.500,00 TL eksik gerçekleşmiştir. | D13: nan | E13: nan
A14: TLREF Endeksli Senetler | B14: 2025 | C14: TRT061228T16 | D14: 15.01.2025 | E14: 06.12.2028 | F14: 1421 | G14: 3 ay | I14: 49270032 | J14: 51262429 | K14: 16874000 | L14: 17661324 | M14: 2866260.3 | N14: 3000000 | O14: 33439703 | P14: 35000000 | Q14: 4284423.3 | R14: 4484334.5 | S14: 57464387 | T14: 60145659 | U14: 12.5 | V14: 60.15 | W14: 104.666
A15: TLREF Endeksli Senetler | B15: 2025 | C15: TRT061228T16 | D15: 19.02.2025 | E15: 06.12.2028 | F15: 1386 | G15: 3 ay | I15: 75514318 | J15: 82300767 | K15: 20501318 | L15: 22438293 | M15: 2741027.7 | N15: 3000000 | O15: 13705139 | P15: 15000000 | Q15: 7709161 | R15: 8437522.5 | S15: 44656645 | T15: 48875816 | U15: 12.51 | V15: 60.21 | W15: 109.448
A16: TLREF Endeksli Senetler | B16: 2025 | C16: TRT070329T15 | D16: 12.03.2025 | E16: 07.03.2029 | F16: 1456 | G16: 3 ay | I16: 52389000 | J16: 51236840 | K16: 30269000 | L16: 29794013 | M16: 6603610.7 | N16: 6500000 | O16: 7619550.7 | P16: 7500000 | Q16: 6652834.1 | R16: 6548451.1 | S16: 51144995 | T16: 50342464 | U16: 10.83 | V16: 50.88 | W16: 98.431
A17: TLREF Endeksli Senetler | B17: 2025 | C17: TRT080426T16 | D17: 09.04.2025 | E17: 08.04.2026 | F17: 364 | G17: 3 ay | I17: 1.0015502e+08 | J17: 97925951 | K17: 48823020 | L17: 48195551 | M17: 0 | N17: 0 | O17: 30390518 | P17: 30000000 | Q17: 110418.88 | R17: 109000 | S17: 79323957 | T17: 78304551 | U17: 12.05 | V17: 57.65 | W17: 98.715
A18: TLREF Endeksli Senetler | B18: 2025 | C18: TRT070329T15 | D18: 14.05.2025 | E18: 07.03.2029 | F18: 1393 | G18: 3 ay | I18: 74609000 | J18: 74840593 | K18: 39461000 | L18: 39857749 | M18: 2970150 | N18: 3000000 | O18: 14850750 | P18: 15000000 | Q18: 16764389 | R18: 16932871 | S18: 74046289 | T18: 74790620 | U18: 11.5 | V18: 54.57 | W18: 101.005
A19: TLREF Endeksli Senetler | B19: 2025 | C19: TRT130629T30 | D19: 18.06.2025 | E19: 13.06.2029 | F19: 1456 | G19: 3 ay | I19: 81751004 | J19: 75981893 | K19: 50419004 | L19: 47098581 | M19: 2676258.4 | N19: 2500000 | O19: 18198557 | P19: 17000000 | Q19: 20501647 | R19: 19151408 | S19: 91795466 | T19: 85749990 | U19: 12.47 | V19: 60 | W19: 93.414
A20: TLREF Endeksli Senetler | B20: 2025 | C20: TRT040729T14 | D20: 09.07.2025 | E20: 04.07.2029 | F20: 1456 | G20: 6 ay | I20: 101867278 | J20: 95052769 | K20: 32615000 | L20: 30774210 | M20: 9538344.1 | N20: 9000000 | O20: 40273009 | P20: 38000000 | Q20: 12202729 | R20: 11514007 | S20: 94629081 | T20: 89288216 | U20: 24.68 | V20: 55.45 | W20: 94.356
A21: TLREF Endeksli Senetler | B21: 2025 | C21: TRT040729T14 | D21: 20.08.2025 | E21: 04.07.2029 | F21: 1414 | G21: 6 ay | I21: 179552851 | J21: 1.8104531e+08 | K21: 27285000 | L21: 27707455 | M21: 7917438.1 | N21: 8040000 | O21: 31512191 | P21: 32000000 | Q21: 9419403.6 | R21: 9565216 | S21: 76134033 | T21: 77312671 | U21: 23.98 | V21: 53.72 | W21: 101.548
A22: TLREF Endeksli Senetler | B22: 2024 | C22: TRT190128T14 | D22: 24.01.2024 | E22: 19.01.2028 | F22: 1456 | G22: 3 ay | I22: 38392211 | J22: 37023569 | K22: 5910000 | L22: 5864075 | M22: 0 | N22: 0 | O22: 10078308 | P22: 10000000 | Q22: 3010000 | R22: 2986612.3 | S22: 18998308 | T22: 18850687 | U22: 10.72 | V22: 50.3 | W22: 99.223
A23: TLREF Endeksli Senetler | B23: 2024 | C23: TRT190128T14 | D23: 14.02.2024 | E23: 19.01.2028 | F23: 1435 | G23: 3 ay | I23: 29462003 | J23: 29493318 | K23: 7170000 | L23: 7319549.7 | M23: 0 | N23: 0 | O23: 5877397.5 | P23: 6000000 | Q23: 1961824 | R23: 2002747.6 | S23: 15009221 | T23: 15322297 | U23: 10.66 | V23: 49.93 | W23: 102.086
A24: TLREF Endeksli Senetler | B24: 2024 | C24: TRT190128T14 | D24: 13.03.2024 | E24: 19.01.2028 | F24: 1407 | G24: 3 ay | I24: 19044000 | J24: 19695210 | K24: 6310000 | L24: 6633671.5 | M24: 0 | N24: 0 | O24: 4280414.7 | P24: 4500000 | Q24: 3245940.9 | R24: 3412457.7 | S24: 13836356 | T24: 14546129 | U24: 10.68 | V24: 50.07 | W24: 105.13
A25: TLREF Endeksli Senetler | B25: 2024 | C25: TRT190128T14 | D25: 17.04.2024 | E25: 19.01.2028 | F25: 1372 | G25: 3 ay | I25: 25895005 | J25: 28269890 | K25: 12800000 | L25: 14045439 | M25: 0 | N25: 0 | O25: 8201950.2 | P25: 9000000 | Q25: 5125110.1 | R25: 5623783.3 | S25: 26127060 | T25: 28669222 | U25: 10.62 | V25: 49.76 | W25: 109.73
... A61: TLREF Endeksli Senetler | B61: 2021 | C61: TRT130127T11 | D61: 20.10.2021 | E61: 13.01.2027 | F61: 1911 | G61: 3 ay | I61: 1956001 | J61: 1879141.5 | K61: 611001 | L61: 592442.31 | M61: 0 | N61: 0 | O61: 773490.92 | P61: 750000 | Q61: 155866.41 | R61: 151132.75 | S61: 1540358.3 | T61: 1493575.1 | U61: 5.19 | V61: 22.44 | W61: 96.963
A62: TLREF Endeksli Senetler | B62: 2021 | C62: TRT130127T11 | D62: 10.11.2021 | E62: 13.01.2027 | F62: 1890 | G62: 3 ay | I62: 1514000 | J62: 1446712.1 | K62: 300000 | L62: 292099.05 | M62: 77028.942 | N62: 75000 | O62: 333792.08 | P62: 325000 | Q62: - | R62: - | S62: 710821.02 | T62: 692099.05 | U62: 5.25 | V62: 22.72 | W62: 97.366
A63: TLREF Endeksli Senetler | B63: 2020 | C63: TRT260122T11 | D63: 29.01.2020 | E63: 26.01.2022 | F63: 728 | G63: 3 ay | I63: 9789750 | J63: 9745880.9 | K63: 2140700 | L63: 2146697.3 | M63: 648185.08 | N63: 650000 | O63: 1246509.8 | P63: 1250000 | Q63: 634242.12 | R63: 636018 | S63: 4669637 | T63: 4682715.3 | U63: 2.46 | V63: 10.21 | W63: 100.28
A64: TLREF Endeksli Senetler | B64: 2020 | C64: TRT260122T11 | D64: 26.02.2020 | E64: 26.01.2022 | F64: 700 | G64: 3 ay | I64: 3563330.6 | J64: 3563099.6 | K64: 1850330.6 | L64: 1864659.5 | M64: 0 | N64: 0 | O64: 1190783.3 | P64: 1200000 | Q64: 0 | R64: 0 | S64: 3041113.9 | T64: 3064659.5 | U64: 2.5 | V64: 10.37 | W64: 100.774
A65: TLREF Endeksli Senetler | B65: 2020 | C65: TRT210623T10 | D65: 25.03.2020 | E65: 21.06.2023 | F65: 1183 | G65: 3 ay | I65: 2492000 | J65: 2474935 | K65: 2167000 | L65: 2161092.5 | M65: 0 | N65: 0 | O65: 1403832.5 | P65: 1400000 | Q65: 0 | R65: 0 | S65: 3570832.5 | T65: 3561092.5 | U65: 2.52 | V65: 10.49 | W65: 99.727
A66: TLREF Endeksli Senetler | B66: 2020 | C66: TRT210623T10 | D66: 08.04.2020 | E66: 21.06.2023 | F66: 1169 | G66: 3 ay | I66: 4503000 | J66: 4450136.2 | K66: 3718000 | L66: 3685173.2 | M66: 0 | N66: 0 | O66: 2522271.7 | P66: 2500000 | Q66: 0 | R66: 0 | S66: 6240271.7 | T66: 6185173.2 | U66: 2.62 | V66: 10.89 | W66: 99.117
A67: TLREF Endeksli Senetler | B67: 2020 | C67: TRT210623T10 | D67: 13.05.2020 | E67: 21.06.2023 | F67: 1134 | G67: 3 ay | I67: 6015000 | J67: 6018106.4 | K67: 3510000 | L67: 3528348.4 | M67: 0 | N67: 0 | O67: 1492195.8 | P67: 1500000 | Q67: 0 | R67: 0 | S67: 5002195.8 | T67: 5028348.4 | U67: 2.58 | V67: 10.71 | W67: 100.523
A68: TLREF Endeksli Senetler | B68: 2020 | C68: TRT210623T10 | D68: 17.06.2020 | E68: 21.06.2023 | F68: 1099 | G68: 3 ay | I68: 3659200 | J68: 3702398.2 | K68: 1673000 | L68: 1701212.9 | M68: 0 | N68: 0 | O68: 1475129.3 | P68: 1500000 | Q68: 600 | R68: 610.116 | S68: 3148729.3 | T68: 3201823 | U68: 2.56 | V68: 10.64 | W68: 101.686
A69: TLREF Endeksli Senetler | B69: 2020 | C69: TRT170724T14 | D69: 22.07.2020 | E69: 17.07.2024 | F69: 1456 | G69: 3 ay | I69: 3057001 | J69: 3013522.9 | K69: 1208000 | L69: 1196907.8 | M69: 0 | N69: 0 | O69: 1614824.1 | P69: 1600000 | Q69: 24000 | R69: 23779.68 | S69: 2846824.1 | T69: 2820687.5 | U69: 2.57 | V69: 10.69 | W69: 99.082
A70: TLREF Endeksli Senetler | B70: 2020 | C70: TRT170724T14 | D70: 12.08.2020 | E70: 17.07.2024 | F70: 1435 | G70: 3 ay | I70: 3437000 | J70: 3367727.8 | K70: 2187000 | L70: 2168142.9 | M70: 0 | N70: 0 | O70: 1008694.9 | P70: 1000000 | Q70: 60010.288 | R70: 59492.999 | S70: 3255705.2 | T70: 3227635.9 | U70: 2.61 | V70: 10.86 | W70: 99.138
A71: TLREF Endeksli Senetler | B71: 2020 | C71: TRT170724T14 | D71: 16.09.2020 | E71: 17.07.2024 | F71: 1400 | G71: 3 ay | I71: 3577000 | J71: 3565572.5 | K71: 825000 | L71: 834835.5 | M71: 143291.96 | N71: 145000 | O71: 889398.37 | P71: 900000 | Q71: 0 | R71: 0 | S71: 1857690.3 | T71: 1879835.5 | U71: 2.53 | V71: 10.5 | W71: 101.192
A72: TLREF Endeksli Senetler | B72: 2020 | C72: TRT170724T14 | D72: 07.10.2020 | E72: 17.07.2024 | F72: 1379 | G72: 3 ay | I72: 6318000 | J72: 6388712.5 | K72: 1773000 | L72: 1806340.9 | M72: 54966.627 | N72: 56000 | O72: 1472320.4 | P72: 1500000 | Q72: 399200 | R72: 406704.96 | S72: 3699487 | T72: 3769045.9 | U72: 2.52 | V72: 10.46 | W72: 101.88
A73: TL Cinsi Kira Sertifikalari | B73: 2012 | C73: TRD011014T17 | D73: 03.10.2012 | E73: 01.10.2014 | F73: 728 | G73: 6 Ay | H73: 3.7 | K73: 1624482.6 | L73: 1624482.6 | W73: 100
A74: TL Cinsi Kira Sertifikalari | B74: 2013 | C74: TRD180215T17 | D74: 20.02.2013 | E74: 18.02.2015 | F74: 728 | G74: 6 Ay | H74: 2.85 | K74: 1515326.8 | L74: 1515326.8 | W74: 100
A75: TL Cinsi Kira Sertifikalari | B75: 2013 | C75: TRD190815T10 | D75: 21.08.2013 | E75: 19.08.2015 | F75: 728 | G75: 6 Ay | H75: 4.5 | K75: 1817300 | L75: 1817300 | W75: 100
...

Sheet TLREF Endeksli Senetler
A1: Genel Bilgiler | I1: Teklif Edilen Tutar | K1: İhale Kabul Edilen Tutar | M1: Rek. Olmayan Teklif - Kamu | O1: Rek. Olmayan Teklif - Piyasa Yapıcı | Q1: İhale Sonrası Satış | S1: Toplam Satış | U1: Kabul Edilen Faiz (%) | W1: Fiyat
A2: Senet Türü | B2: Yıl | C2: ISIN Kodu | D2: Valör Tarihi | E2: İtfa Tarihi | F2: Vade (Gün) | G2: Kupon Dönemi | H2: Kupon Oranı (%) | I2: Nominal (Bin TL) | J2: Net (Bin TL) | K2: Nominal (Bin TL) | L2: Net (Bin TL) | M2: Nominal (Bin TL) | N2: Net (Bin TL) | O2: Nominal (Bin TL) | P2: Net (Bin TL) | Q2: Nominal (Bin TL) | R2: Net (Bin TL) | S2: Nominal (Bin TL) | T2: Net (Bin TL) | U2: Ort. Dönem (Basit) | V2: Ort. Yıllık Bileşik | W2: İhraç Birim Fiyatı (Ort.)
A3: TLREF Endeksli Senetler | B3: 2026 | C3: TRT090130T12 | D3: 14.01.2026 | E3: 09.01.2030 | F3: 1456 | G3: 6 ay | I3: 79609005 | J3: 78023610 | K3: 29589001 | L3: 29392788 | M3: 22247501 | N3: 22100000 | O3: 23153508 | P3: 23000000 | Q3: 2098463.6 | R3: 2084550.8 | S3: 77088473 | T3: 76577339 | U3: 18.77 | V3: 41.05 | W3: 99.337
A4: TLREF Endeksli Senetler | B4: 2026 | C4: TRT090130T12 | D4: 11.02.2026 | E4: 09.01.2030 | F4: 1428 | G4: 6 ay | I4: 56562000 | J4: 58027619 | K4: 31595000 | L4: 32495975 | M4: 14972971 | N4: 15400000 | O4: 13611792 | P4: 14000000 | Q4: 8396267 | R4: 8635728.5 | S4: 68576030 | T4: 70531703 | U4: 18.55 | V4: 40.54 | W4: 102.852
A5: TLREF Endeksli Senetler | B5: 2026 | C5: TRT090130T12 | D5: 18.03.2026 | E5: 09.01.2030 | F5: 1393 | G5: 6 ay | I5: 81525000 | J5: 83978061 | K5: 16613000 | L5: 17209377 | M5: 9682401.8 | N5: 10030000 | O5: 19789555 | P5: 20500000 | Q5: 2606759.8 | R5: 2700342.5 | S5: 48691717 | T5: 50439720 | U5: 19.25 | V5: 42.19 | W5: 103.59
A6: TLREF Endeksli Senetler | B6: 2026 | C6: TRT090130T12 | D6: 08.04.2026 | E6: 09.01.2030 | F6: 1372 | G6: 6 ay | I6: 101723858 | J6: 1.0671121e+08 | K6: 62860858 | L6: 66117448 | M6: 190148.41 | N6: 200000 | O6: 31849859 | P6: 33500000 | Q6: 23923511 | R6: 25162988 | S6: 1.1882438e+08 | T6: 1.2498044e+08 | U6: 19.39 | V6: 42.53 | W6: 105.181
A7: TLREF Endeksli Senetler | B7: 2026 | C7: TRT090130T12 | D7: 13.05.2026 | E7: 09.01.2030 | F7: 1337 | G7: 6 ay | I7: 122200001 | J7: 1.3337384e+08 | K7: 40607001 | L7: 44450411 | M7: 1863609.4 | N7: 2040000 | O7: 36541360 | P7: 40000000 | Q7: 18248574 | R7: 19975802 | S7: 97260545 | T7: 1.0646621e+08 | U7: 19.22 | V7: 42.12 | W7: 109.465
A8: TLREF Endeksli Senetler | B8: 2026 | C8: TRT090130T12 | D8: 10.06.2026 | E8: 09.01.2030 | F8: 1309 | G8: 6 ay | I8: 104246000 | J8: 1.1700454e+08 | K8: 60642000 | L8: 68135035 | M8: 3586813.3 | N8: 4030000 | O8: 50731603 | P8: 57000000 | Q8: 25428457 | R8: 28570397 | S8: 1.4038887e+08 | T8: 1.5773543e+08 | U8: 19.25 | V8: 42.19 | W8: 112.356
A9: TLREF Endeksli Senetler | B9: 2026 | C9: TRT030730T12* | D9: 08.07.2026 | E9: 03.07.2030 | F9: 1456 | G9: 6 ay | I9: 1.4623886e+08 | J9: 1.4287476e+08 | K9: 75869822 | L9: 74576049 | M9: 3764179.3 | N9: 3700000 | O9: 80370314 | P9: 79000000 | Q9: 508672.87 | R9: 500000 | S9: 1.6051299e+08 | T9: 1.5777605e+08 | U9: 20.45 | V9: 45.08 | W9: 98.295
A10: TLREF Endeksli Senetler | B10: 2026 | C10: TRT030730T12 | D10: 19.08.2026 | E10: 03.07.2030 | F10: 1414 | G10: 6 ay | I10: 128932100 | J10: 1.3194076e+08 | K10: 32323100 | L10: 33159966 | M10: 97476.337 | N10: 99999.999 | O10: 53611986 | P10: 55000000 | Q10: 14802107 | R10: 15185333 | S10: 1.0083467e+08 | T10: 1.034453e+08 | U10: 20.46 | V10: 45.09 | W10: 102.589
A11: TLREF Endeksli Senetler | B11: 2026 | C11: TRT110930T36 | D11: 16.09.2026 | E11: 11.09.2030 | F11: 1456 | G11: 6 ay | I11: 113114000 | J11: 1.1046897e+08 | K11: 49631000 | L11: 48851315 | M11: 5486188 | N11: 5400000 | O11: 30478822 | P11: 30000000 | Q11: 0 | R11: 0 | S11: 85596010 | T11: 84251315 | U11: 18.64 | V11: 40.76 | W11: 98.429
A12: TLREF Endeksli Senetler | B12: 2026 | C12: TRT110930T36 | D12: 07.10.2026 | E12: 11.09.2030 | F12: 1435 | G12: 6 ay | I12: 58939000 | J12: 58617039 | K12: 26298000 | L12: 26217249 | M12: 0 | N12: 0 | O12: 25076986 | P12: 25000000 | Q12: 5300499.5 | R12: 5284227 | S12: 56675486 | T12: 56501476 | U12: 18.82 | V12: 41.18 | W12: 99.693
A13: TLREF Endeksli Senetler | B13: 2026 | C13: (*) İlgili ihalede yükümlülüğün yerine getirilmemesi sebebiyle, ihalede kabul edilen tutar ve toplam satış tutarlarında yukarıda belirtilen istatistiklerden nominal satış tutarı 175.000.000,00 TL; net satış tutarı ise 203.234.500,00 TL eksik gerçekleşmiştir. | D13: nan | E13: nan
A14: TLREF Endeksli Senetler | B14: 2025 | C14: TRT061228T16 | D14: 15.01.2025 | E14: 06.12.2028 | F14: 1421 | G14: 3 ay | I14: 49270032 | J14: 51262429 | K14: 16874000 | L14: 17661324 | M14: 2866260.3 | N14: 3000000 | O14: 33439703 | P14: 35000000 | Q14: 4284423.3 | R14: 4484334.5 | S14: 57464387 | T14: 60145659 | U14: 12.5 | V14: 60.15 | W14: 104.666
A15: TLREF Endeksli Senetler | B15: 2025 | C15: TRT061228T16 | D15: 19.02.2025 | E15: 06.12.2028 | F15: 1386 | G15: 3 ay | I15: 75514318 | J15: 82300767 | K15: 20501318 | L15: 22438293 | M15: 2741027.7 | N15: 3000000 | O15: 13705139 | P15: 15000000 | Q15: 7709161 | R15: 8437522.5 | S15: 44656645 | T15: 48875816 | U15: 12.51 | V15: 60.21 | W15: 109.448
A16: TLREF Endeksli Senetler | B16: 2025 | C16: TRT070329T15 | D16: 12.03.2025 | E16: 07.03.2029 | F16: 1456 | G16: 3 ay | I16: 52389000 | J16: 51236840 | K16: 30269000 | L16: 29794013 | M16: 6603610.7 | N16: 6500000 | O16: 7619550.7 | P16: 7500000 | Q16: 6652834.1 | R16: 6548451.1 | S16: 51144995 | T16: 50342464 | U16: 10.83 | V16: 50.88 | W16: 98.431
A17: TLREF Endeksli Senetler | B17: 2025 | C17: TRT080426T16 | D17: 09.04.2025 | E17: 08.04.2026 | F17: 364 | G17: 3 ay | I17: 1.0015502e+08 | J17: 97925951 | K17: 48823020 | L17: 48195551 | M17: 0 | N17: 0 | O17: 30390518 | P17: 30000000 | Q17: 110418.88 | R17: 109000 | S17: 79323957 | T17: 78304551 | U17: 12.05 | V17: 57.65 | W17: 98.715
A18: TLREF Endeksli Senetler | B18: 2025 | C18: TRT070329T15 | D18: 14.05.2025 | E18: 07.03.2029 | F18: 1393 | G18: 3 ay | I18: 74609000 | J18: 74840593 | K18: 39461000 | L18: 39857749 | M18: 2970150 | N18: 3000000 | O18: 14850750 | P18: 15000000 | Q18: 16764389 | R18: 16932871 | S18: 74046289 | T18: 74790620 | U18: 11.5 | V18: 54.57 | W18: 101.005
A19: TLREF Endeksli Senetler | B19: 2025 | C19: TRT130629T30 | D19: 18.06.2025 | E19: 13.06.2029 | F19: 1456 | G19: 3 ay | I19: 81751004 | J19: 75981893 | K19: 50419004 | L19: 47098581 | M19: 2676258.4 | N19: 2500000 | O19: 18198557 | P19: 17000000 | Q19: 20501647 | R19: 19151408 | S19: 91795466 | T19: 85749990 | U19: 12.47 | V19: 60 | W19: 93.414
A20: TLREF Endeksli Senetler | B20: 2025 | C20: TRT040729T14 | D20: 09.07.2025 | E20: 04.07.2029 | F20: 1456 | G20: 6 ay | I20: 101867278 | J20: 95052769 | K20: 32615000 | L20: 30774210 | M20: 9538344.1 | N20: 9000000 | O20: 40273009 | P20: 38000000 | Q20: 12202729 | R20: 11514007 | S20: 94629081 | T20: 89288216 | U20: 24.68 | V20: 55.45 | W20: 94.356
A21: TLREF Endeksli Senetler | B21: 2025 | C21: TRT040729T14 | D21: 20.08.2025 | E21: 04.07.2029 | F21: 1414 | G21: 6 ay | I21: 179552851 | J21: 1.8104531e+08 | K21: 27285000 | L21: 27707455 | M21: 7917438.1 | N21: 8040000 | O21: 31512191 | P21: 32000000 | Q21: 9419403.6 | R21: 9565216 | S21: 76134033 | T21: 77312671 | U21: 23.98 | V21: 53.72 | W21: 101.548
A22: TLREF Endeksli Senetler | B22: 2024 | C22: TRT190128T14 | D22: 24.01.2024 | E22: 19.01.2028 | F22: 1456 | G22: 3 ay | I22: 38392211 | J22: 37023569 | K22: 5910000 | L22: 5864075 | M22: 0 | N22: 0 | O22: 10078308 | P22: 10000000 | Q22: 3010000 | R22: 2986612.3 | S22: 18998308 | T22: 18850687 | U22: 10.72 | V22: 50.3 | W22: 99.223
A23: TLREF Endeksli Senetler | B23: 2024 | C23: TRT190128T14 | D23: 14.02.2024 | E23: 19.01.2028 | F23: 1435 | G23: 3 ay | I23: 29462003 | J23: 29493318 | K23: 7170000 | L23: 7319549.7 | M23: 0 | N23: 0 | O23: 5877397.5 | P23: 6000000 | Q23: 1961824 | R23: 2002747.6 | S23: 15009221 | T23: 15322297 | U23: 10.66 | V23: 49.93 | W23: 102.086
A24: TLREF Endeksli Senetler | B24: 2024 | C24: TRT190128T14 | D24: 13.03.2024 | E24: 19.01.2028 | F24: 1407 | G24: 3 ay | I24: 19044000 | J24: 19695210 | K24: 6310000 | L24: 6633671.5 | M24: 0 | N24: 0 | O24: 4280414.7 | P24: 4500000 | Q24: 3245940.9 | R24: 3412457.7 | S24: 13836356 | T24: 14546129 | U24: 10.68 | V24: 50.07 | W24: 105.13
A25: TLREF Endeksli Senetler | B25: 2024 | C25: TRT190128T14 | D25: 17.04.2024 | E25: 19.01.2028 | F25: 1372 | G25: 3 ay | I25: 25895005 | J25: 28269890 | K25: 12800000 | L25: 14045439 | M25: 0 | N25: 0 | O25: 8201950.2 | P25: 9000000 | Q25: 5125110.1 | R25: 5623783.3 | S25: 26127060 | T25: 28669222 | U25: 10.62 | V25: 49.76 | W25: 109.73
... A61: TLREF Endeksli Senetler | B61: 2021 | C61: TRT130127T11 | D61: 20.10.2021 | E61: 13.01.2027 | F61: 1911 | G61: 3 ay | I61: 1956001 | J61: 1879141.5 | K61: 611001 | L61: 592442.31 | M61: 0 | N61: 0 | O61: 773490.92 | P61: 750000 | Q61: 155866.41 | R61: 151132.75 | S61: 1540358.3 | T61: 1493575.1 | U61: 5.19 | V61: 22.44 | W61: 96.963
A62: TLREF Endeksli Senetler | B62: 2021 | C62: TRT130127T11 | D62: 10.11.2021 | E62: 13.01.2027 | F62: 1890 | G62: 3 ay | I62: 1514000 | J62: 1446712.1 | K62: 300000 | L62: 292099.05 | M62: 77028.942 | N62: 75000 | O62: 333792.08 | P62: 325000 | Q62: - | R62: - | S62: 710821.02 | T62: 692099.05 | U62: 5.25 | V62: 22.72 | W62: 97.366
A63: TLREF Endeksli Senetler | B63: 2020 | C63: TRT260122T11 | D63: 29.01.2020 | E63: 26.01.2022 | F63: 728 | G63: 3 ay | I63: 9789750 | J63: 9745880.9 | K63: 2140700 | L63: 2146697.3 | M63: 648185.08 | N63: 650000 | O63: 1246509.8 | P63: 1250000 | Q63: 634242.12 | R63: 636018 | S63: 4669637 | T63: 4682715.3 | U63: 2.46 | V63: 10.21 | W63: 100.28
A64: TLREF Endeksli Senetler | B64: 2020 | C64: TRT260122T11 | D64: 26.02.2020 | E64: 26.01.2022 | F64: 700 | G64: 3 ay | I64: 3563330.6 | J64: 3563099.6 | K64: 1850330.6 | L64: 1864659.5 | M64: 0 | N64: 0 | O64: 1190783.3 | P64: 1200000 | Q64: 0 | R64: 0 | S64: 3041113.9 | T64: 3064659.5 | U64: 2.5 | V64: 10.37 | W64: 100.774
A65: TLREF Endeksli Senetler | B65: 2020 | C65: TRT210623T10 | D65: 25.03.2020 | E65: 21.06.2023 | F65: 1183 | G65: 3 ay | I65: 2492000 | J65: 2474935 | K65: 2167000 | L65: 2161092.5 | M65: 0 | N65: 0 | O65: 1403832.5 | P65: 1400000 | Q65: 0 | R65: 0 | S65: 3570832.5 | T65: 3561092.5 | U65: 2.52 | V65: 10.49 | W65: 99.727
A66: TLREF Endeksli Senetler | B66: 2020 | C66: TRT210623T10 | D66: 08.04.2020 | E66: 21.06.2023 | F66: 1169 | G66: 3 ay | I66: 4503000 | J66: 4450136.2 | K66: 3718000 | L66: 3685173.2 | M66: 0 | N66: 0 | O66: 2522271.7 | P66: 2500000 | Q66: 0 | R66: 0 | S66: 6240271.7 | T66: 6185173.2 | U66: 2.62 | V66: 10.89 | W66: 99.117
A67: TLREF Endeksli Senetler | B67: 2020 | C67: TRT210623T10 | D67: 13.05.2020 | E67: 21.06.2023 | F67: 1134 | G67: 3 ay | I67: 6015000 | J67: 6018106.4 | K67: 3510000 | L67: 3528348.4 | M67: 0 | N67: 0 | O67: 1492195.8 | P67: 1500000 | Q67: 0 | R67: 0 | S67: 5002195.8 | T67: 5028348.4 | U67: 2.58 | V67: 10.71 | W67: 100.523
A68: TLREF Endeksli Senetler | B68: 2020 | C68: TRT210623T10 | D68: 17.06.2020 | E68: 21.06.2023 | F68: 1099 | G68: 3 ay | I68: 3659200 | J68: 3702398.2 | K68: 1673000 | L68: 1701212.9 | M68: 0 | N68: 0 | O68: 1475129.3 | P68: 1500000 | Q68: 600 | R68: 610.116 | S68: 3148729.3 | T68: 3201823 | U68: 2.56 | V68: 10.64 | W68: 101.686
A69: TLREF Endeksli Senetler | B69: 2020 | C69: TRT170724T14 | D69: 22.07.2020 | E69: 17.07.2024 | F69: 1456 | G69: 3 ay | I69: 3057001 | J69: 3013522.9 | K69: 1208000 | L69: 1196907.8 | M69: 0 | N69: 0 | O69: 1614824.1 | P69: 1600000 | Q69: 24000 | R69: 23779.68 | S69: 2846824.1 | T69: 2820687.5 | U69: 2.57 | V69: 10.69 | W69: 99.082
A70: TLREF Endeksli Senetler | B70: 2020 | C70: TRT170724T14 | D70: 12.08.2020 | E70: 17.07.2024 | F70: 1435 | G70: 3 ay | I70: 3437000 | J70: 3367727.8 | K70: 2187000 | L70: 2168142.9 | M70: 0 | N70: 0 | O70: 1008694.9 | P70: 1000000 | Q70: 60010.288 | R70: 59492.999 | S70: 3255705.2 | T70: 3227635.9 | U70: 2.61 | V70: 10.86 | W70: 99.138
A71: TLREF Endeksli Senetler | B71: 2020 | C71: TRT170724T14 | D71: 16.09.2020 | E71: 17.07.2024 | F71: 1400 | G71: 3 ay | I71: 3577000 | J71: 3565572.5 | K71: 825000 | L71: 834835.5 | M71: 143291.96 | N71: 145000 | O71: 889398.37 | P71: 900000 | Q71: 0 | R71: 0 | S71: 1857690.3 | T71: 1879835.5 | U71: 2.53 | V71: 10.5 | W71: 101.192
A72: TLREF Endeksli Senetler | B72: 2020 | C72: TRT170724T14 | D72: 07.10.2020 | E72: 17.07.2024 | F72: 1379 | G72: 3 ay | I72: 6318000 | J72: 6388712.5 | K72: 1773000 | L72: 1806340.9 | M72: 54966.627 | N72: 56000 | O72: 1472320.4 | P72: 1500000 | Q72: 399200 | R72: 406704.96 | S72: 3699487 | T72: 3769045.9 | U72: 2.52 | V72: 10.46 | W72: 101.88

Sheet TL Cinsi Kira Sertifikalari
A1: Genel Bilgiler | I1: Teklif Edilen Tutar | K1: İhale Kabul Edilen Tutar | M1: Rek. Olmayan Teklif - Kamu | O1: Rek. Olmayan Teklif - Piyasa Yapıcı | Q1: İhale Sonrası Satış | S1: Toplam Satış | U1: Kabul Edilen Faiz (%) | W1: Fiyat
A2: Senet Türü | B2: Yıl | C2: ISIN Kodu | D2: Valör Tarihi | E2: İtfa Tarihi | F2: Vade (Gün) | G2: Kupon Dönemi | H2: Kupon Oranı (%) | I2: Nominal (Bin TL) | J2: Net (Bin TL) | K2: Nominal (Bin TL) | L2: Net (Bin TL) | M2: Nominal (Bin TL) | N2: Net (Bin TL) | O2: Nominal (Bin TL) | P2: Net (Bin TL) | Q2: Nominal (Bin TL) | R2: Net (Bin TL) | S2: Nominal (Bin TL) | T2: Net (Bin TL) | U2: Ort. Dönem (Basit) | V2: Ort. Yıllık Bileşik | W2: İhraç Birim Fiyatı (Ort.)
A3: TL Cinsi Kira Sertifikalari | B3: 2012 | C3: TRD011014T17 | D3: 03.10.2012 | E3: 01.10.2014 | F3: 728 | G3: 6 Ay | H3: 3.7 | K3: 1624482.6 | L3: 1624482.6 | W3: 100
A4: TL Cinsi Kira Sertifikalari | B4: 2013 | C4: TRD180215T17 | D4: 20.02.2013 | E4: 18.02.2015 | F4: 728 | G4: 6 Ay | H4: 2.85 | K4: 1515326.8 | L4: 1515326.8 | W4: 100
A5: TL Cinsi Kira Sertifikalari | B5: 2013 | C5: TRD190815T10 | D5: 21.08.2013 | E5: 19.08.2015 | F5: 728 | G5: 6 Ay | H5: 4.5 | K5: 1817300 | L5: 1817300 | W5: 100
A6: TL Cinsi Kira Sertifikalari | B6: 2014 | C6: TRD170216T17 | D6: 19.02.2014 | E6: 17.02.2016 | F6: 728 | G6: 6 Ay | H6: 5.3 | K6: 1332820 | L6: 1332820 | W6: 100
A7: TL Cinsi Kira Sertifikalari | B7: 2014 | C7: TRD280916T17 | D7: 01.10.2014 | E7: 28.09.2016 | F7: 728 | G7: 6 Ay | H7: 4.84 | K7: 1839964.1 | L7: 1839964.1 | W7: 100
A8: TL Cinsi Kira Sertifikalari | B8: 2015 | C8: TRD150217T18 | D8: 18.02.2015 | E8: 15.02.2017 | F8: 728 | G8: 6 Ay | H8: 3.9 | K8: 1801515.3 | L8: 1801515.3 | W8: 100
A9: TL Cinsi Kira Sertifikalari | B9: 2015 | C9: TRD160817T11 | D9: 19.08.2015 | E9: 16.08.2017 | F9: 728 | G9: 6 Ay | H9: 4.98 | K9: 1588783.9 | L9: 1588783.9 | W9: 100
A10: TL Cinsi Kira Sertifikalari | B10: 2016 | C10: TRD140218T18 | D10: 17.02.2016 | E10: 14.02.2018 | F10: 728 | G10: 6 Ay | H10: 5.32 | K10: 1900352.3 | L10: 1900352.3 | W10: 100
A11: TL Cinsi Kira Sertifikalari | B11: 2016 | C11: TRD140721T18 | D11: 20.07.2016 | E11: 14.07.2021 | F11: 1820 | G11: 6 Ay | H11: 4.7 | K11: 907500 | L11: 907500 | W11: 100
A12: TL Cinsi Kira Sertifikalari | B12: 2016 | C12: TRD260918T17 | D12: 28.09.2016 | E12: 26.09.2018 | F12: 728 | G12: 6 Ay | H12: 4.4 | K12: 1102839.2 | L12: 1102839.2 | W12: 100
A13: TL Cinsi Kira Sertifikalari | B13: 2016 | C13: TRD220921T16 | D13: 28.09.2016 | E13: 22.09.2021 | F13: 1820 | G13: 6 Ay | H13: 1.12 | K13: 1066565.1 | L13: 1066565.1 | W13: 100
A14: TL Cinsi Kira Sertifikalari | B14: 2016 | C14: TRD211118T18 | D14: 23.11.2016 | E14: 21.11.2018 | F14: 728 | G14: 6 Ay | H14: 5.08 | K14: 1285000 | L14: 1285000 | W14: 100
... A43: TL Cinsi Kira Sertifikalari | B43: 2021 | C43: TRD120723T18 | D43: 14.07.2021 | E43: 12.07.2023 | F43: 728 | G43: 6 Ay | H43: 9.04 | K43: 1143740 | L43: 1143740 | W43: 100
A44: TL Cinsi Kira Sertifikalari | C44: TRD160823T13 | D44: 18.08.2021 | E44: 16.08.2023 | F44: 728 | G44: 6 Ay | H44: 8.9 | K44: 921700 | L44: 921700 | W44: 100
A45: TL Cinsi Kira Sertifikalari | B45: 2021 | C45: TRD160926T19 | D45: 22.09.2021 | E45: 16.09.2026 | F45: 1820 | G45: 6 Ay | H45: 8.4 | K45: 725000 | L45: 725000 | W45: 100
A46: TL Cinsi Kira Sertifikalari | B46: 2021 | C46: TRD181023T17 | D46: 20.10.2021 | E46: 18.10.2023 | F46: 728 | G46: 6 Ay | H46: 9.05 | K46: 1914500 | L46: 1914500 | W46: 100
A47: TL Cinsi Kira Sertifikalari | B47: 2021 | C47: TRD131223T10 | D47: 15.12.2021 | E47: 13.12.2023 | F47: 728 | G47: 6 Ay | H47: 10.16 | K47: 2992530 | L47: 2992530 | W47: 100
A48: TL Cinsi Kira Sertifikalari | B48: 2022 | C48: TRD200127T10 | D48: 26.01.2022 | E48: 20.01.2027 | F48: 1820 | G48: 6 Ay | H48: 0 | K48: 11111100 | L48: 13333320 | W48: 120
A49: TL Cinsi Kira Sertifikalari | B49: 2022 | C49: TRD140224T10 | D49: 16.02.2022 | E49: 14.02.2024 | F49: 728 | G49: 6 Ay | H49: 10.1 | K49: 5561460 | L49: 5561460 | W49: 100
A50: TL Cinsi Kira Sertifikalari | B50: 2022 | C50: TRD200324T29 | D50: 23.03.2022 | E50: 20.03.2024 | F50: 728 | G50: 6 Ay | H50: 12.15 | K50: 4098810 | L50: 4098810 | W50: 100
A51: TL Cinsi Kira Sertifikalari | B51: 2022 | C51: TRD070432T17 | D51: 20.04.2022 | E51: 07.04.2032 | F51: 3640 | G51: 6 Ay | H51: 0 | K51: 8644000 | L51: 11064320 | W51: 128
A52: TL Cinsi Kira Sertifikalari | B52: 2022 | C52: TRD080524T15 | D52: 11.05.2022 | E52: 08.05.2024 | F52: 728 | G52: 6 Ay | H52: 11.35 | K52: 2271520 | L52: 2271520 | W52: 100
A53: TL Cinsi Kira Sertifikalari | B53: 2022 | C53: TRD230632T15 | D53: 06.07.2022 | E53: 23.06.2032 | F53: 3640 | G53: 6 Ay | H53: 9.04 | K53: 8240030 | L53: 8240030 | W53: 100
A54: TL Cinsi Kira Sertifikalari | B54: 2022 | C54: TRD040832T16 | D54: 17.08.2022 | E54: 04.08.2032 | F54: 3640 | G54: 6 Ay | H54: 8.07 | K54: 10290430 | L54: 10290430 | W54: 100
A55: TL Cinsi Kira Sertifikalari | B55: 2022 | C55: TRD080927T18 | D55: 14.09.2022 | E55: 08.09.2027 | F55: 1820 | G55: 6 Ay | H55: 5.09 | K55: 19718500 | L55: 19718500 | W55: 100
A56: TL Cinsi Kira Sertifikalari | B56: 2022 | C56: TRD061027T17 | D56: 12.10.2022 | E56: 06.10.2027 | F56: 1820 | G56: 6 Ay | H56: 5.23 | K56: 11484000 | L56: 11484000 | W56: 100
... A95: TL Cinsi Kira Sertifikalari | B95: 2026 | C95: TRD041028T26 | D95: 07.10.2026 | E95: 04.10.2028 | F95: 728 | G95: 6 Ay | H95: 18.9 | K95: 59255500 | L95: 59255500 | W95: 100

Sheet TL Cinsi Kuponsuz Senetler
A1: Genel Bilgiler | I1: Teklif Edilen Tutar | K1: İhale Kabul Edilen Tutar | M1: Rek. Olmayan Teklif - Kamu | O1: Rek. Olmayan Teklif - Piyasa Yapıcı | Q1: İhale Sonrası Satış | S1: Toplam Satış | U1: Kabul Edilen Faiz (%) | W1: Fiyat
A2: Senet Türü | B2: Yıl | C2: ISIN Kodu | D2: Valör Tarihi | E2: İtfa Tarihi | F2: Vade (Gün) | G2: Kupon Dönemi | H2: Kupon Oranı (%) | I2: Nominal (Bin TL) | J2: Net (Bin TL) | K2: Nominal (Bin TL) | L2: Net (Bin TL) | M2: Nominal (Bin TL) | N2: Net (Bin TL) | O2: Nominal (Bin TL) | P2: Net (Bin TL) | Q2: Nominal (Bin TL) | R2: Net (Bin TL) | S2: Nominal (Bin TL) | T2: Net (Bin TL) | U2: Ort. Dönem (Basit) | V2: Ort. Yıllık Bileşik | W2: İhraç Birim Fiyatı (Ort.)
A3: TL Cinsi Kuponsuz Senetler | B3: 2026 | C3: TRT060127T10 | D3: 07.01.2026 | E3: 06.01.2027 | F3: 364 | I3: 86764373 | J3: 63303336 | K3: 38149825 | L3: 27918968 | M3: 3279495 | N3: 2400000 | O3: 21863300 | P3: 16000000 | Q3: 11914728 | R3: 8719436.2 | S3: 75207348 | T3: 55038404 | U3: 36.64 | V3: 36.64 | W3: 73.182
A4: TL Cinsi Kuponsuz Senetler | B4: 2026 | C4: TRT060127T10 | D4: 11.02.2026 | E4: 06.01.2027 | F4: 329 | I4: 55702054 | J4: 42172668 | K4: 15325245 | L4: 11664499 | M4: 1313836 | N4: 1000000 | O4: 3941508 | P4: 3000000 | Q4: 6920380.2 | R4: 5267309 | S4: 27500969 | T4: 20931808 | U4: 31.38 | V4: 35.25 | W4: 76.113
A5: TL Cinsi Kuponsuz Senetler | B5: 2026 | C5: TRT060127T10 | D5: 11.03.2026 | E5: 06.01.2027 | F5: 301 | I5: 36640334 | J5: 27782187 | K5: 11543831 | L5: 8831242.8 | M5: 24509163 | N5: 18750000 | O5: 6535776.8 | P5: 5000000 | Q5: 4245222.2 | R5: 3247679.9 | S5: 46833993 | T5: 35828923 | U5: 30.72 | V5: 38.25 | W5: 76.502
A6: TL Cinsi Kuponsuz Senetler | B6: 2026 | C6: TRB170327T15 | D6: 08.04.2026 | E6: 17.03.2027 | F6: 343 | I6: 33278500 | J6: 23579670 | K6: 15836500 | L6: 11330430 | M6: 314482.99 | N6: 225000 | O6: 9783915.2 | P6: 7000000 | Q6: 5678397.7 | R6: 4062666.4 | S6: 31613296 | T6: 22618096 | U6: 39.77 | V6: 42.66 | W6: 71.546
A7: TL Cinsi Kuponsuz Senetler | B7: 2026 | C7: TRB170327T15 | D7: 06.05.2026 | E7: 17.03.2027 | F7: 315 | I7: 33625633 | J7: 24659834 | K7: 20819633 | L7: 15322423 | M7: 951138.65 | N7: 700000 | O7: 10870156 | P7: 8000000 | Q7: 6757230.3 | R7: 4973051.2 | S7: 39398158 | T7: 28995474 | U7: 35.88 | V7: 42.51 | W7: 73.596
A8: TL Cinsi Kuponsuz Senetler | B8: 2026 | C8: TRB100227T13 | D8: 17.06.2026 | E8: 10.02.2027 | F8: 238 | I8: 92542421 | J8: 73286937 | K8: 27366584 | L8: 21725993 | M8: 30419831 | N8: 24150000 | O8: 32750129 | P8: 26000000 | Q8: 9698184.7 | R8: 7699291.9 | S8: 1.0023473e+08 | T8: 79575284 | U8: 25.96 | V8: 42.33 | W8: 79.389
A9: TL Cinsi Kuponsuz Senetler | B9: 2026 | C9: TRB100227T13 | D9: 22.07.2026 | E9: 10.02.2027 | F9: 203 | I9: 90138208 | J9: 74178247 | K9: 52688917 | L9: 43425255 | M9: 13831930 | N9: 11400000 | O9: 7279963.1 | P9: 6000000 | Q9: 22178424 | R9: 18279014 | S9: 95979234 | T9: 79104269 | U9: 21.33 | V9: 41.44 | W9: 82.418
A10: TL Cinsi Kuponsuz Senetler | B10: 2026 | C10: TRB100227T13 | D10: 12.08.2026 | E10: 10.02.2027 | F10: 182 | I10: 1.3398242e+08 | J10: 1.126422e+08 | K10: 49116474 | L10: 41343992 | M10: 7128007.1 | N10: 6000000 | O10: 32076032 | P10: 27000000 | Q10: 22707825 | R10: 19114312 | S10: 1.1102834e+08 | T10: 93458304 | U10: 18.8 | V10: 41.13 | W10: 84.175
A11: TL Cinsi Kuponsuz Senetler | B11: 2025 | C11: TRB230725T15 | D11: 22.01.2025 | E11: 23.07.2025 | F11: 182 | I11: 60390700 | J11: 50016786 | K11: 21593600 | L11: 17996378 | M11: 59994.48 | N11: 50000 | O11: 11998896 | P11: 10000000 | Q11: 10377035 | R11: 8648324.4 | S11: 44029525 | T11: 36694703 | U11: 19.99 | V11: 43.97 | W11: 83.341
A12: TL Cinsi Kuponsuz Senetler | B12: 2025 | C12: TRB230725T15 | D12: 12.02.2025 | E12: 23.07.2025 | F12: 161 | I12: 32903775 | J12: 28014078 | K12: 13083075 | L12: 11161317 | M12: 58609.089 | N12: 50000 | O12: 11721818 | P12: 10000000 | Q12: 5921005.3 | R12: 5051268.9 | S12: 30784507 | T12: 26262586 | U12: 17.22 | V12: 43.21 | W12: 85.311
A13: TL Cinsi Kuponsuz Senetler | B13: 2025 | C13: TRB230725T15 | D13: 16.04.2025 | E13: 23.07.2025 | F13: 98 | I13: 17595173 | J13: 15622159 | K13: 5448102 | L13: 4887810.4 | M13: 0 | N13: 0 | O13: 2786571 | P13: 2500000 | Q13: 1736267.5 | R13: 1557709.8 | S13: 9970940.5 | T13: 8945520.2 | U13: 11.46 | V13: 49.64 | W13: 89.716
A14: TL Cinsi Kuponsuz Senetler | B14: 2025 | C14: TRB110326T12 | D14: 11.06.2025 | E14: 11.03.2026 | F14: 273 | I14: 21616000 | J14: 16148858 | K14: 11771000 | L14: 8825634.4 | M14: 2734135.3 | N14: 2050000 | O14: 3334311.4 | P14: 2500000 | Q14: 4306148 | R14: 3228663.6 | S14: 22145595 | T14: 16604298 | U14: 33.37 | V14: 46.81 | W14: 74.978
... A23: TL Cinsi Kuponsuz Senetler | B23: 2024 | C23: TRT090425T16 | D23: 13.03.2024 | E23: 09.04.2025 | F23: 392 | I23: 4513000 | J23: 2917905.2 | K23: 594000 | L23: 388442.8 | M23: 0 | N23: 0 | O23: 1911490.3 | P23: 1250000 | Q23: 181007.69 | R23: 118368.17 | S23: 2686498 | T23: 1756811 | U23: 52.92 | V23: 48.35 | W23: 65.394
A24: TL Cinsi Kuponsuz Senetler | B24: 2024 | C24: TRT090425T16 | D24: 17.04.2024 | E24: 09.04.2025 | F24: 357 | I24: 8910000 | J24: 5900685.7 | K24: 1757000 | L24: 1185063.4 | M24: 2223935.5 | N24: 1500000 | O24: 518918.28 | P24: 350000 | Q24: - | R24: - | S24: 4499853.8 | T24: 3035063.4 | U24: 48.26 | V24: 49.41 | W24: 67.448
A25: TL Cinsi Kuponsuz Senetler | B25: 2024 | C25: TRT090425T16 | D25: 08.05.2024 | E25: 09.04.2025 | F25: 336 | I25: 8417000 | J25: 5730230.9 | K25: 2469000 | L25: 1692680.4 | M25: 3646600.6 | N25: 2500000 | O25: 1021048.2 | P25: 700000 | Q25: 993994.78 | R25: 681453 | S25: 8130643.6 | T25: 5574133.4 | U25: 45.86 | V25: 50.52 | W25: 68.557
A26: TL Cinsi Kuponsuz Senetler | B26: 2024 | C26: TRT090425T16 | D26: 12.06.2024 | E26: 09.04.2025 | F26: 301 | I26: 15199000 | J26: 10816347 | K26: 3649000 | L26: 2609900 | M26: 6990660.5 | N26: 5000000 | O26: 4893462.3 | P26: 3500000 | Q26: 1370630.7 | R26: 980329.92 | S26: 16903754 | T26: 12090230 | U26: 39.81 | V26: 49.97 | W26: 71.524
A27: TL Cinsi Kuponsuz Senetler | B27: 2024 | C27: TRT090425T16 | D27: 10.07.2024 | E27: 09.04.2025 | F27: 273 | I27: 27463005 | J27: 20317860 | K27: 6025000 | L27: 4475774.2 | M27: 3432632.9 | N27: 2550000 | O27: 6730652.7 | P27: 5000000 | Q27: 1125196.2 | R27: 835874.5 | S27: 17313482 | T27: 12861649 | U27: 34.61 | V27: 48.63 | W27: 74.287
A28: TL Cinsi Kuponsuz Senetler | B28: 2024 | C28: TRT100925T18 | D28: 21.08.2024 | E28: 10.09.2025 | F28: 385 | I28: 34700150 | J28: 23200468 | K28: 7694150 | L28: 5221390.3 | M28: 2298782.8 | N28: 1560000 | O28: 6631104.3 | P28: 4500000 | Q28: 1869018.6 | R28: 1268353.4 | S28: 18493056 | T28: 12549744 | U28: 47.36 | V28: 44.27 | W28: 67.862
A29: TL Cinsi Kuponsuz Senetler | B29: 2024 | C29: TRT100925T18 | D29: 11.09.2024 | E29: 10.09.2025 | F29: 364 | I29: 6271000 | J29: 4262010 | K29: 3166000 | L29: 2170508.4 | M29: 2917280.5 | N29: 2000000 | O29: 5834561 | P29: 4000000 | Q29: - | R29: - | S29: 11917842 | T29: 8170508.4 | U29: 45.86 | V29: 45.86 | W29: 68.557
A30: TL Cinsi Kuponsuz Senetler | B30: 2024 | C30: TRT100925T18 | D30: 09.10.2024 | E30: 10.09.2025 | F30: 336 | I30: 21472220 | J30: 14851913 | K30: 9694183.7 | L30: 6755549 | M30: 4304963.6 | N30: 3000000 | O30: 3228722.7 | P30: 2250000 | Q30: 2685785 | R30: 1871643 | S30: 19913655 | T30: 13877192 | U30: 43.5 | V30: 47.88 | W30: 69.687
A31: TL Cinsi Kuponsuz Senetler | B31: 2024 | C31: TRT100925T18 | D31: 06.11.2024 | E31: 10.09.2025 | F31: 308 | I31: 15800230 | J31: 11293579 | K31: 5490000 | L31: 3940950.1 | M31: 0 | N31: 0 | O31: 3482670.2 | P31: 2500000 | Q31: 2281609.3 | R31: 1637830.4 | S31: 11254280 | T31: 8078780.6 | U31: 39.31 | V31: 47.96 | W31: 71.784
A32: TL Cinsi Kuponsuz Senetler | B32: 2024 | C32: TRT100925T18 | D32: 11.12.2024 | E32: 10.09.2025 | F32: 273 | I32: 25169000 | J32: 18827811 | K32: 6639000 | L32: 5017729.8 | M32: 5358560.5 | N32: 4050000 | O32: 661550.67 | P32: 500000 | Q32: 1634302.6 | R32: 1235205.9 | S32: 14293414 | T32: 10802936 | U32: 32.31 | V32: 45.25 | W32: 75.58
A33: TL Cinsi Kuponsuz Senetler | B33: 2023 | C33: TRT131223T12 | D33: 18.01.2023 | E33: 13.12.2023 | F33: 329 | I33: 1422000 | J33: 1292928.1 | K33: 533000 | L33: 486057.72 | M33: 328972.62 | N33: 300000 | O33: 137071.92 | P33: 125000 | Q33: 30003.618 | R33: 27361.199 | S33: 1029048.2 | T33: 938418.92 | U33: 9.66 | V33: 10.74 | W33: 91.193
A34: TL Cinsi Kuponsuz Senetler | B34: 2023 | C34: TRT131223T12 | D34: 08.03.2023 | E34: 13.12.2023 | F34: 280 | I34: 1346000 | J34: 1249938.6 | K34: 936000 | L34: 870350.99 | M34: 0 | N34: 0 | O34: 1290516.9 | P34: 1200000 | Q34: 0 | R34: 0 | S34: 2226516.9 | T34: 2070351 | U34: 7.54 | V34: 9.91 | W34: 92.986
A35: TL Cinsi Kuponsuz Senetler | B35: 2023 | C35: TRT161024T10 | D35: 19.07.2023 | E35: 16.10.2024 | F35: 455 | I35: 1265000 | J35: 986195.4 | K35: 325000 | L35: 266954.35 | M35: 1217433.6 | N35: 1000000 | O35: 30435.84 | P35: 24999.999 | Q35: 0 | R35: 0 | S35: 1572869.5 | T35: 1291954.3 | U35: 21.74 | V35: 17.05 | W35: 82.14
A36: TL Cinsi Kuponsuz Senetler | B36: 2023 | C36: TRT161024T10 | D36: 18.10.2023 | E36: 16.10.2024 | F36: 364 | I36: 3330001.8 | J36: 2462714.3 | K36: 1030001.8 | L36: 815226.35 | M36: 1895183.7 | N36: 1500000 | O36: 37903.673 | P36: 29999.999 | Q36: 0 | R36: 0 | S36: 2963089.2 | T36: 2345226.3 | U36: 26.35 | V36: 26.35 | W36: 79.148
A37: TL Cinsi Kuponsuz Senetler | B37: 2023 | C37: TRT161024T10 | D37: 08.11.2023 | E37: 16.10.2024 | F37: 343 | I37: 6561007 | J37: 4621859.4 | K37: 1581007 | L37: 1151183.5 | M37: 0 | N37: 0 | O37: 137338.11 | P37: 99999.998 | Q37: 0 | R37: 0 | S37: 1718345.1 | T37: 1251183.5 | U37: 37.34 | V37: 40.03 | W37: 72.813
A38: TL Cinsi Kuponsuz Senetler | B38: 2022 | C38: TRT250123T11 | D38: 12.01.2022 | E38: 25.01.2023 | F38: 378 | I38: 3244010 | J38: 2589066.4 | K38: 1772010 | L38: 1420132.2 | M38: 499114.07 | N38: 400000 | O38: 998228.14 | P38: 800000 | Q38: 776000 | R38: 621901.92 | S38: 4045352.2 | T38: 3242034.1 | U38: 24.78 | V38: 23.76 | W38: 80.142
A39: TL Cinsi Kuponsuz Senetler | B39: 2022 | C39: TRT250123T11 | D39: 16.02.2022 | E39: 25.01.2023 | F39: 343 | I39: 6779010 | J39: 5713621.2 | K39: 1416010 | L39: 1198626.8 | M39: 1004158.4 | N39: 850000 | O39: 2539930.1 | P39: 2150000 | Q39: 0 | R39: 0 | S39: 4960098.5 | T39: 4198626.8 | U39: 18.14 | V39: 19.35 | W39: 84.648
A40: TL Cinsi Kuponsuz Senetler | B40: 2022 | C40: TRT250123T11 | D40: 09.03.2022 | E40: 25.01.2023 | F40: 322 | I40: 5277000 | J40: 4396263.8 | K40: 2436000 | L40: 2036769.3 | M40: 0 | N40: 0 | O40: 2152826.8 | P40: 1800000 | Q40: 25012.857 | R40: 20913.5 | S40: 4613839.6 | T40: 3857682.8 | U40: 19.6 | V40: 22.43 | W40: 83.611
A41: TL Cinsi Kuponsuz Senetler | B41: 2022 | C41: TRB220223T13 | D41: 13.04.2022 | E41: 22.02.2023 | F41: 315 | I41: 3865028.3 | J41: 3234798.9 | K41: 2265028.3 | L41: 1898437 | M41: 119310.38 | N41: 99999.999 | O41: 1312414.2 | P41: 1100000 | Q41: 345248.25 | R41: 289369.82 | S41: 4042001.2 | T41: 3387806.9 | U41: 19.31 | V41: 22.63 | W41: 83.815
... A61: TL Cinsi Kuponsuz Senetler | B61: 2020 | C61: TRB091220T11 | D61: 27.05.2020 | E61: 09.12.2020 | F61: 196 | I61: 1867000 | J61: 1790414.6 | K61: 846000 | L61: 811529.74 | M61: 0 | N61: 0 | O61: 1042470.2 | P61: 1000000 | Q61: 27608.089 | R61: 26483.335 | S61: 1916078.3 | T61: 1838013.1 | U61: 4.25 | V61: 8.03 | W61: 95.926
A62: TL Cinsi Kuponsuz Senetler | B62: 2020 | C62: TRT090621T18 | D62: 10.06.2020 | E62: 09.06.2021 | F62: 364 | I62: 2260005.5 | J62: 2081744.5 | K62: 925000 | L62: 852900.45 | M62: 433815.95 | N62: 400000 | O62: 759177.92 | P62: 700000 | Q62: - | R62: - | S62: 2117993.9 | T62: 1952900.4 | U62: 8.45 | V62: 8.45 | W62: 92.205
A63: TL Cinsi Kuponsuz Senetler | B63: 2020 | C63: TRB091220T11 | D63: 17.06.2020 | E63: 09.12.2020 | F63: 175 | I63: 3202000 | J63: 3080920 | K63: 1018000 | L63: 980092.29 | M63: 0 | N63: 0 | O63: 1558020.7 | P63: 1500000 | Q63: - | R63: - | S63: 2576020.7 | T63: 2480092.3 | U63: 3.87 | V63: 8.21 | W63: 96.276
A64: TL Cinsi Kuponsuz Senetler | B64: 2020 | C64: TRT180821T15 | D64: 22.07.2020 | E64: 18.08.2021 | F64: 392 | I64: 2252055.6 | J64: 2039744.8 | K64: 602000 | L64: 545779.21 | M64: 0 | N64: 0 | O64: 1103010.1 | P64: 1000000 | Q64: 0 | R64: 0 | S64: 1705010.1 | T64: 1545779.2 | U64: 10.3 | V64: 9.53 | W64: 90.661
A65: TL Cinsi Kuponsuz Senetler | B65: 2019 | C65: TRT150120T32 | D65: 16.01.2019 | E65: 15.01.2020 | F65: 364 | I65: 600200 | J65: 502998.54 | K65: 380000 | L65: 319368.66 | M65: 856694.11 | N65: 720000 | O65: 956641.76 | P65: 804000 | Q65: 0 | R65: 0 | S65: 2193335.9 | T65: 1843368.7 | U65: 18.98 | V65: 18.98 | W65: 84.044
A66: TL Cinsi Kuponsuz Senetler | B66: 2019 | C66: TRT150120T32 | D66: 13.02.2019 | E66: 15.01.2020 | F66: 336 | I66: 888000 | J66: 753021.2 | K66: 618000 | L66: 525263.25 | M66: 1176553.6 | N66: 1000000 | O66: 1158905.3 | P66: 985000 | Q66: 0 | R66: 0 | S66: 2953459 | T66: 2510263.2 | U66: 17.66 | V66: 19.26 | W66: 84.994
A67: TL Cinsi Kuponsuz Senetler | B67: 2019 | C67: TRT111219T10 | D67: 20.03.2019 | E67: 11.12.2019 | F67: 266 | I67: 2052000 | J67: 1793960.8 | K67: 1117000 | L67: 977837.25 | M67: 721947.43 | N67: 632000 | O67: 1313670.2 | P67: 1150000 | Q67: 0 | R67: 0 | S67: 3152617.6 | T67: 2759837.2 | U67: 14.23 | V67: 19.97 | W67: 87.541
...

Sheet TL Cinsi TUFE Endeksli Senetler
A1: Genel Bilgiler | I1: Teklif Edilen Tutar | K1: İhale Kabul Edilen Tutar | M1: Rek. Olmayan Teklif - Kamu | O1: Rek. Olmayan Teklif - Piyasa Yapıcı | Q1: İhale Sonrası Satış | S1: Toplam Satış | U1: Kabul Edilen Faiz (%) | W1: Fiyat
A2: Senet Türü | B2: Yıl | C2: ISIN Kodu | D2: Valör Tarihi | E2: İtfa Tarihi | F2: Vade (Gün) | G2: Kupon Dönemi | H2: Kupon Oranı (%) | I2: Nominal (Bin TL) | J2: Net (Bin TL) | K2: Nominal (Bin TL) | L2: Net (Bin TL) | M2: Nominal (Bin TL) | N2: Net (Bin TL) | O2: Nominal (Bin TL) | P2: Net (Bin TL) | Q2: Nominal (Bin TL) | R2: Net (Bin TL) | S2: Nominal (Bin TL) | T2: Net (Bin TL) | U2: Ort. Dönem (Basit) | V2: Ort. Yıllık Bileşik | W2: İhraç Birim Fiyatı (Ort.)
A3: TL Cinsi TUFE Endeksli Senetler | B3: 2026 | C3: TRT080131T12 | D3: 14.01.2026 | E3: 08.01.2031 | F3: 1820 | G3: 6 ay | H3: 2.65 | I3: 7111000 | J3: 6889380.8 | K3: 650000 | L3: 650109 | M3: 19996601 | N3: 20000000 | O3: 1999660.1 | P3: 2000000 | Q3: 0 | R3: 0 | S3: 22646261 | T3: 22650109 | U3: 2.65 | V3: 5.37 | W3: 100.017
A4: TL Cinsi TUFE Endeksli Senetler | B4: 2026 | C4: TRT080131T12 | D4: 18.02.2026 | E4: 08.01.2031 | F4: 1785 | G4: 6 ay | H4: 2.65 | I4: 6209675 | J4: 6249049.2 | K4: 4320175 | L4: 4386747 | M4: 7386179 | N4: 7500000 | O4: 837100.28 | P4: 850000 | Q4: 2992492.1 | R4: 3038606.4 | S4: 15535946 | T4: 15775353 | U4: 2.65 | V4: 5.37 | W4: 101.541
A5: TL Cinsi TUFE Endeksli Senetler | B5: 2026 | C5: TRT080131T12 | D5: 11.03.2026 | E5: 08.01.2031 | F5: 1764 | G5: 6 ay | H5: 2.65 | I5: 9650000 | J5: 10041330 | K5: 6250000 | L5: 6524546.5 | M5: 4789593.2 | N5: 5000000 | O5: 1436877.9 | P5: 1500000 | Q5: 1326717.3 | R5: 1385000 | S5: 13803188 | T5: 14409546 | U5: 2.58 | V5: 5.23 | W5: 104.393
A6: TL Cinsi TUFE Endeksli Senetler | B6: 2026 | C6: TRT080131T12 | D6: 08.04.2026 | E6: 08.01.2031 | F6: 1736 | G6: 6 ay | H6: 2.65 | I6: 9010000 | J6: 9727906.1 | K6: 6950000 | L6: 7540993.7 | M6: 4608125 | N6: 5000000 | O6: 2488387.5 | P6: 2700000 | Q6: 480000 | R6: 520819.2 | S6: 14526513 | T6: 15761813 | U6: 2.63 | V6: 5.33 | W6: 108.504
A7: TL Cinsi TUFE Endeksli Senetler | B7: 2026 | C7: TRT080530T27 | D7: 13.05.2026 | E7: 08.05.2030 | F7: 1456 | G7: 6 ay | H7: 2.63 | I7: 5130000 | J7: 5080404.7 | K7: 3630000 | L7: 3610525.7 | M7: 2010777.8 | N7: 2000000 | O7: 2714550 | P7: 2700000 | Q7: 0 | R7: 0 | S7: 8355327.8 | T7: 8310525.7 | U7: 2.71 | V7: 5.48 | W7: 99.464
A8: TL Cinsi TUFE Endeksli Senetler | B8: 2026 | C8: TRT080530T27 | D8: 10.06.2026 | E8: 08.05.2030 | F8: 1428 | G8: 6 ay | H8: 2.63 | I8: 8715000 | J8: 8855818.2 | K8: 6465000 | L8: 6585798.7 | M8: 3926611.6 | N8: 4000000 | O8: 2552297.6 | P8: 2600000 | Q8: 0 | R8: 0 | S8: 12943909 | T8: 13185799 | U8: 2.77 | V8: 5.61 | W8: 101.869
A9: TL Cinsi TUFE Endeksli Senetler | B9: 2026 | C9: TRT080530T27 | D9: 19.08.2026 | E9: 08.05.2030 | F9: 1358 | G9: 6 ay | H9: 2.63 | I9: 640150 | J9: 682608.5 | K9: 190000 | L9: 204458.25 | M9: 3717126.7 | N9: 4000000 | O9: 418176.75 | P9: 450000 | Q9: 0 | R9: 0 | S9: 4325303.4 | T9: 4654458.2 | U9: 2.87 | V9: 5.83 | W9: 107.61
A10: TL Cinsi TUFE Endeksli Senetler | B10: 2025 | C10: TRT151227T16 | D10: 22.01.2025 | E10: 15.12.2027 | F10: 1057 | G10: 6 ay | H10: 1.5 | I10: 8652000 | J10: 8308408 | K10: 5975000 | L10: 5810790 | M10: 6272364.6 | N10: 6100000 | O10: 2056513 | P10: 2000000 | Q10: 0 | R10: 0 | S10: 14303878 | T10: 13910790 | U10: 2.57 | V10: 5.2 | W10: 97.252
A11: TL Cinsi TUFE Endeksli Senetler | B11: 2025 | C11: TRT151227T16 | D11: 19.02.2025 | E11: 15.12.2027 | F11: 1029 | G11: 6 ay | H11: 1.5 | I11: 12903000 | J11: 12661178 | K11: 5363000 | L11: 5306982.8 | M11: 13177707 | N11: 13040000 | O11: 3031681.1 | P11: 3000000 | Q11: 2213484.9 | R11: 2190354 | S11: 23785873 | T11: 23537337 | U11: 2.57 | V11: 5.21 | W11: 98.955
A12: TL Cinsi TUFE Endeksli Senetler | B12: 2025 | C12: TRT151227T16 | D12: 19.03.2025 | E12: 15.12.2027 | F12: 1001 | G12: 6 ay | H12: 1.5 | I12: 14209000 | J12: 14439628 | K12: 5755000 | L12: 5910286.3 | M12: 7327309.2 | N12: 7525000 | O12: 3894915.2 | P12: 4000000 | Q12: 0 | R12: 0 | S12: 16977224 | T12: 17435286 | U12: 2.56 | V12: 5.18 | W12: 102.698
A13: TL Cinsi TUFE Endeksli Senetler | B13: 2025 | C13: TRT110429T18 | D13: 16.04.2025 | E13: 11.04.2029 | F13: 1456 | G13: 6 ay | H13: 2.5 | I13: 12105000 | J13: 11798996 | K13: 6845000 | L13: 6878188.4 | M13: 34831069 | N13: 35000000 | O13: 4975867 | P13: 5000000 | Q13: 0 | R13: 0 | S13: 46651936 | T13: 46878188 | U13: 2.43 | V13: 4.92 | W13: 100.485
A14: TL Cinsi TUFE Endeksli Senetler | B14: 2025 | C14: TRT110429T18 | D14: 14.05.2025 | E14: 11.04.2029 | F14: 1428 | G14: 6 ay | H14: 2.5 | I14: 6869000 | J14: 6824630.5 | K14: 880000 | L14: 886977 | M14: 6448860.5 | N14: 6500000 | O14: 1488198.6 | P14: 1500000 | Q14: 0 | R14: 0 | S14: 8817059.1 | T14: 8886977 | U14: 2.75 | V14: 5.57 | W14: 100.793
... A117: TL Cinsi TUFE Endeksli Senetler | B117: 2014 | C117: TRT180924T11 | D117: 01.10.2014 | E117: 18.09.2024 | F117: 3640 | G117: 6 Ay | H117: 1 | I117: 3413017.1 | J117: 3371811.2 | K117: 1656017.1 | L117: 1646299.9 | M117: 0 | N117: 0 | O117: 884622.74 | P117: 879430 | Q117: 100366.15 | R117: 99777 | S117: 2641006 | T117: 2625506.9 | U117: 1.03 | V117: 2.08 | W117: 99.25
A118: TL Cinsi TUFE Endeksli Senetler | B118: 2013 | C118: TRT261022T10 | D118: nan | E118: nan | I118: 3477320.7 | J118: 3776812.5 | K118: 1022000 | L118: 1118681.2 | M118: 548145.44 | N118: 600000 | O118: 324940.62 | P118: 355680 | Q118: 235250.84 | R118: 257505.57 | S118: 2130336.9 | T118: 2331866.8 | U118: 0.68 | V118: 1.36 | W118: 109.46
A119: TL Cinsi TUFE Endeksli Senetler | B119: 2013 | C119: TRT261022T10 | D119: nan | E119: nan | I119: 3232102.5 | J119: 3645041.3 | K119: 760000 | L119: 864831 | M119: 1417034.3 | N119: 1612500 | O119: 314535.04 | P119: 357922 | Q119: 120150.1 | R119: 136723.6 | S119: 2611719.4 | T119: 2971976.6 | U119: 0.5 | V119: 1.01 | W119: 113.794
A120: TL Cinsi TUFE Endeksli Senetler | B120: 2013 | C120: TRT261022T10 | D120: nan | E120: nan | I120: 3308900 | J120: 3806219.1 | K120: 852600 | L120: 991227 | M120: 967667.02 | N120: 1125000 | O120: 309588.94 | P120: 359925 | Q120: 111956.21 | R120: 130159.17 | S120: 2241812.2 | T120: 2606311.2 | U120: 0.48 | V120: 0.96 | W120: 116.259
A121: TL Cinsi TUFE Endeksli Senetler | B121: 2013 | C121: TRT030523T13 | D121: nan | E121: nan | I121: 4666810 | J121: 4672410.4 | K121: 998000 | L121: 1004022.9 | M121: 993996.26 | N121: 1000000 | O121: 562303.69 | P121: 565700 | Q121: 0 | R121: 0 | S121: 2554299.9 | T121: 2569722.9 | U121: 0.47 | V121: 0.94 | W121: 100.604
A122: TL Cinsi TUFE Endeksli Senetler | B122: 2013 | C122: TRT030523T13 | D122: nan | E122: nan | I122: 1338400 | J122: 1116763.1 | K122: 922100 | L122: 776867.71 | M122: 130563.8 | N122: 110000 | O122: 1627062.3 | P122: 1370800 | Q122: 0 | R122: 0 | S122: 2679726.1 | T122: 2257667.7 | U122: 1.47 | V122: 2.95 | W122: 84.25
A123: TL Cinsi TUFE Endeksli Senetler | B123: 2013 | C123: TRT030523T13 | D123: nan | E123: nan | I123: 4009881 | J123: 3260990.3 | K123: 1747600 | L123: 1442273.3 | M123: 575555.26 | N123: 475000 | O123: 1335966.8 | P123: 1102560 | Q123: 258513.15 | R123: 213348.32 | S123: 3917635.2 | T123: 3233181.7 | U123: 1.59 | V123: 3.22 | W123: 82.529
A124: TL Cinsi TUFE Endeksli Senetler | B124: 2013 | C124: TRT020823T11 | D124: nan | E124: nan | I124: 3994101 | J124: 3986338.9 | K124: 2258300 | L124: 2270113.5 | M124: 119375.67 | N124: 120000 | O124: 1342379.4 | P124: 1349400 | Q124: 30107.517 | R124: 30264.979 | S124: 3750162.5 | T124: 3769778.5 | U124: 1.47 | V124: 2.96 | W124: 100.523
A125: TL Cinsi TUFE Endeksli Senetler | B125: 2013 | C125: TRT020823T11 | D125: nan | E125: nan | I125: 2297120 | J125: 2192548.7 | K125: 1419220 | L125: 1364949.2 | M125: 93994.344 | N125: 90400 | O125: 975919.15 | P125: 938600 | Q125: 227253.31 | R125: 218563.14 | S125: 2716386.8 | T125: 2612512.3 | U125: 1.78 | V125: 3.58 | W125: 96.176
A126: TL Cinsi TUFE Endeksli Senetler | B126: 2013 | C126: TRT020823T11 | D126: nan | E126: nan | I126: 2571100 | J126: 2599931.5 | K126: 755900 | L126: 768646.31 | M126: 355997.88 | N126: 362000 | O126: 733896.5 | P126: 746270 | Q126: 164749.59 | R126: 167527.27 | S126: 2010544 | T126: 2044443.6 | U126: 1.47 | V126: 2.96 | W126: 101.686
A127: TL Cinsi TUFE Endeksli Senetler | B127: 2013 | C127: TRT081123T10 | D127: nan | E127: nan | I127: 5195783.7 | J127: 5243251.7 | K127: 1034500 | L127: 1054102.5 | M127: 785121.94 | N127: 800000 | O127: 557722.89 | P127: 568291.74 | Q127: 126236.04 | R127: 128628.22 | S127: 2503580.9 | T127: 2551022.5 | U127: 1.29 | V127: 2.6 | W127: 101.895
A128: TL Cinsi TUFE Endeksli Senetler | B128: 2012 | C128: TRT210721T11 | D128: nan | E128: nan | I128: 2785600 | J128: 2650620.7 | K128: 1755100 | L128: 1685359.9 | M128: 0 | N128: 0 | O128: 555055.53 | P128: 533000 | Q128: 0 | R128: 0 | S128: 2310155.5 | T128: 2218359.9 | U128: 2.08 | V128: 4.203264 | W128: 96.026429
A129: TL Cinsi TUFE Endeksli Senetler | B129: 2012 | C129: TRT210721T11 | D129: nan | E129: nan | I129: 5381069.7 | J129: 5309007.8 | K129: 1597000 | L129: 1586449.7 | M129: 1258317.5 | N129: 1250000 | O129: 740003.93 | P129: 735112.5 | Q129: 399300 | R129: 396660.63 | S129: 3994621.4 | T129: 3968222.9 | U129: 1.85 | V129: 3.73 | W129: 99.339
... A161: TL Cinsi TUFE Endeksli Senetler | B161: 1999 | C161: TRT090800T11 | D161: nan | E161: nan | I161: 28707 | J161: 2880.8852 | K161: 2880.8852 | L161: 2761.5599 | M161: 0 | N161: 0 | O161: 0 | P161: 0 | Q161: 0 | R161: 0 | S161: 2880.8852 | T161: 2761.5599 | U161: 29.045 | V161: 24.36 | W161: 95.858
A162: TL Cinsi TUFE Endeksli Senetler | B162: 1998 | C162: TRT220199T13 | D162: nan | E162: nan | I162: 319631.41 | L162: 95125 | M162: 0 | N162: 0 | O162: 0 | P162: 0 | Q162: 0 | R162: 0 | T162: 102946 | U162: 18.9
A163: TL Cinsi TUFE Endeksli Senetler | B163: 1998 | C163: TRT240299T10 | D163: nan | E163: nan | I163: 141630 | L163: 123430 | M163: 0 | N163: 0 | O163: 0 | P163: 0 | Q163: 0 | R163: 0 | T163: 133430 | U163: 30.95
A164: TL Cinsi TUFE Endeksli Senetler | B164: 1998 | C164: TRT250399T18 | D164: nan | E164: nan | I164: 241573 | L164: 95986 | M164: 0 | N164: 0 | O164: 0 | P164: 0 | Q164: 0 | R164: 0 | T164: 95986 | U164: 24
A165: TL Cinsi TUFE Endeksli Senetler | B165: 1998 | C165: TRT210499T11 | D165: nan | E165: nan | I165: 248473 | L165: 142730 | M165: 0 | N165: 0 | O165: 0 | P165: 0 | Q165: 0 | R165: 0 | T165: 245250 | U165: 19
A166: TL Cinsi TUFE Endeksli Senetler | B166: 1998 | C166: TRT260599T15 | D166: nan | E166: nan | I166: 190611 | L166: 129111 | M166: 0 | N166: 0 | O166: 0 | P166: 0 | Q166: 0 | R166: 0 | T166: 138301 | U166: 23
A167: TL Cinsi TUFE Endeksli Senetler | B167: 1998 | C167: TRT160699T16 | D167: nan | E167: nan | I167: 290177 | L167: 244327 | M167: 0 | N167: 0 | O167: 0 | P167: 0 | Q167: 0 | R167: 0 | T167: 244327 | U167: 25
A168: TL Cinsi TUFE Endeksli Senetler | B168: 1998 | C168: TRT280799T11 | D168: nan | E168: nan | I168: 458871.5 | L168: 156342.5 | M168: 0 | N168: 0 | O168: 0 | P168: 0 | Q168: 0 | R168: 0 | T168: 164302.5 | U168: 23
A169: TL Cinsi TUFE Endeksli Senetler | B169: 1998 | C169: TRT180899T12 | D169: nan | E169: nan | I169: 230026 | L169: 174376 | M169: 0 | N169: 0 | O169: 0 | P169: 0 | Q169: 0 | R169: 0 | T169: 184315 | U169: 30
A170: TL Cinsi TUFE Endeksli Senetler | B170: 1998 | C170: TRT290999T18 | D170: nan | E170: nan | I170: 39655.3 | L170: 3523.5 | M170: 0 | N170: 0 | O170: 0 | P170: 0 | Q170: 0 | R170: 0 | T170: 58123.5 | U170: 30

Sheet TL Cinsi Sabit Faizli Kuponlu S
A1: Genel Bilgiler | I1: Teklif Edilen Tutar | K1: İhale Kabul Edilen Tutar | M1: Rek. Olmayan Teklif - Kamu | O1: Rek. Olmayan Teklif - Piyasa Yapıcı | Q1: İhale Sonrası Satış | S1: Toplam Satış | U1: Kabul Edilen Faiz (%) | W1: Fiyat
A2: Senet Türü | B2: Yıl | C2: ISIN Kodu | D2: Valör Tarihi | E2: İtfa Tarihi | F2: Vade (Gün) | G2: Kupon Dönemi | H2: Kupon Oranı (%) | I2: Nominal (Bin TL) | J2: Net (Bin TL) | K2: Nominal (Bin TL) | L2: Net (Bin TL) | M2: Nominal (Bin TL) | N2: Net (Bin TL) | O2: Nominal (Bin TL) | P2: Net (Bin TL) | Q2: Nominal (Bin TL) | R2: Net (Bin TL) | S2: Nominal (Bin TL) | T2: Net (Bin TL) | U2: Ort. Dönem (Basit) | V2: Ort. Yıllık Bileşik | W2: İhraç Birim Fiyatı (Ort.)
A3: TL Cinsi Sabit Faizli Kuponlu Senetler | B3: 2026 | C3: TRT021030T18 | D3: 07.01.2026 | E3: 02.10.2030 | F3: 1729 | G3: 6 ay | H3: 16.95 | I3: 76529000 | J3: 88865363 | K3: 29759000 | L3: 34655707 | M3: 11180284 | N3: 13020000 | O3: 20179468 | P3: 23500000 | Q3: 200000 | R3: 232910 | S3: 61318753 | T3: 71408617 | U3: 15.24 | V3: 32.81 | W3: 116.455
A4: TL Cinsi Sabit Faizli Kuponlu Senetler | B4: 2026 | C4: TRT131027T36 | D4: 14.01.2026 | E4: 13.10.2027 | F4: 637 | G4: 6 ay | H4: 18.39 | I4: 70739000 | J4: 79312788 | K4: 22932000 | L4: 25754355 | M4: 8815122.8 | N4: 9900000 | O4: 17808329 | P4: 20000000 | Q4: 3635852.4 | R4: 4083316.7 | S4: 53191304 | T4: 59737671 | U4: 16.99 | V4: 36.87 | W4: 112.307
